Workbook

Sheet Sheet1
A1: Résumé des donnée
D3: Site | E3: Type | F3: Date | G3: Zone | H3: Face | I3: Par | J3: Note
D4: Varenne | E4: Production | F4: 10-09-2025 | G4: Sud-ouest | I4: Julien | J4: Prise de photo avec échelle simple + quelques photo de drone | K4: inconcluent
D5: Varenne | E5: Production | F5: 26-09-2025 | G5: Sud-ouest | I5: Julien | J5: Donnée limité, technique en développement + je voulais tester wipjoint | K5: inconcluent | N5: Géologie varenne
D6: Varenne | E6: Production | F6: 11-11-2025 | I6: Julien | J6: Condition de mise en place difficile
D7: Varenne | E7: SHB | F7: 11-11-2025 | I7: Julien | J7: 4 trous dont deux connectés
D8: Varenne | E8: Production | F8: 24-11-2025 | I8: Julien | J8: Petit blast
E9: SHB | F9: 07-10-2024 | G9: Sud ouest | I9: Masoud | J9: Campagne de single hole 6
E10: Production | F10: 07-10-2024 | G10: Sud ouest | I10: Masoud
B21: Méthodologie pour blast de prod | J21: Info à prendre
B22: Full scan avant blast (essayer d'avoir la face et le top du banc pour pouvoir placer les scan). Surtout s'assurer que tout les trous sont dans les scans pour un modèle complet. | J22: Produit de sautage
J23: Hauteur du banc/longueur trou
J24: Diamètre trou
B25: DRTK pas absolument nécéssaire mais économie de temps lors du traitement de donnée donc si il est libre le prendre | J25: Fardeau/spacing
B26: SCAN de la parois et du top après blast pour évaluation du volume excavé | J26: Stemming
J27: Quantité totale d'explosif
B28: Pour wipfrag, caméra 90 barrée!!! Meilleure la qualité des photos est meilleur les résultats seront. Le temps de compilation sera plus long mais ça sauve du temps de correction manuelle | J28: Séquence
B31: Donner le temps au drone vérifier la clareté des photos!!!
B34: SHB
B35: Meme chose pour les scans
B36: Implantation des trous utiliser le drone et une baguette pour distance
B37: Scan de la position des trous importants
B38: Séparation de chaque paquet de photo pour chaque trou pour avoir des analyse séparée sur WipFrag

Sheet Compilation SHB

Sheet Différent graph fullscale
O26: Sommaire
O27: Blast | P27: Plus gros que 1 m | R27: Dip D | S27: Facteur poudre
O28: 11-11-2024 | P28: 0.2536 | R28: 130 | S28: 0.85
O29: 24-11-2024 | P29: 0.2234 | R29: 54 | S29: 0.79
S49: r

Sheet SHB 2025-11-11
B1: P4-1 | L1: P4-2 | Y1: P4-3-4
B2: P4-1 | L2: P4-2 | S2: P4-3,4 | U2: Trou 4 | Y2: Combinaison 3-4
B3: Dip | C3: 84 | L3: Dip | M3: 86 | S3: Dip | T3: 84 | U3: Dip | V3: 87 | Y3: Dip | Z3: 87
B4: Dip D | C4: 124 | L4: Dip D | M4: 130 | S4: Dip D | T4: 1 | U4: Dip D | V4: 185 | Y4: Dip D | Z4: 1
K5: D | L5: 1 | M5: 212
B6: D | C6: 1 | D6: 198 | K6: D | L6: 5 | M6: 253.74 | V6: Frag
B7: D | C7: 5 | D7: 263.86 | K7: D | L7: 10 | M7: 302 | W7: D | X7: 1 | Y7: 200.65
B8: D | C8: 10 | D8: 323.45 | K8: D | L8: 20 | M8: 366.4 | W8: D | X8: 5 | Y8: 273.85
B9: D | C9: 20 | D9: 396.29 | K9: D | L9: 25 | M9: 397 | W9: D | X9: 10 | Y9: 336.23
B10: D | C10: 25 | D10: 432.71 | K10: D | L10: 30 | M10: 427.6 | W10: D | X10: 20 | Y10: 425.09
B11: D | C11: 30 | D11: 469.14 | K11: D | L11: 40 | M11: 493.7 | W11: D | X11: 25 | Y11: 469.46
B12: D | C12: 40 | D12: 542.18 | K12: D | L12: 50 | M12: 566.9 | W12: D | X12: 30 | Y12: 513.43
B13: D | C13: 50 | D13: 615.21 | K13: D | L13: 60 | M13: 640 | W13: D | X13: 40 | Y13: 601.38
B14: D | C14: 60 | D14: 691.35 | K14: D | L14: 70 | M14: 733.95 | W14: D | X14: 50 | Y14: 693.5
B15: D | C15: 70 | D15: 795.58 | K15: D | L15: 80 | M15: 853.6 | W15: D | X15: 60 | Y15: 825.53
B16: D | C16: 80 | D16: 899.82 | K16: D | L16: 90 | M16: 973.3 | W16: D | X16: 70 | Y16: 957.55
B17: D | C17: 90 | D17: 1017.22 | K17: D | L17: 99 | M17: 1479.21 | W17: D | X17: 80 | Y17: 1395.17
B18: D | C18: 99 | D18: 1415.72 | W18: D | X18: 90 | Y18: 1977.58
B19: Xmax | C19: 1460 | L19: Xmax | M19: 1550 | W19: D | X19: 99 | Y19: 2501
B20: x50 | C20: 600.44 | L20: x50 | M20: 555.32 | X20: Xmax | Y20: 2560
B21: Xc | C21: 697.38 | L21: Xc | M21: 649.26 | X21: x50 | Y21: 695.59
B22: n | C22: 4.29 | L22: n | M22: 4.36 | X22: Xc | Y22: 865.08
B23: b | C23: 3.75 | L23: b | M23: 4.19 | X23: n | Y23: 3.95
B24: x90 | C24: =D17 -> 1017.22 | L24: x90 | M24: =M16 -> 973.3 | X24: b | Y24: 4.39
X25: x90 | Y25: =Y17 -> 1395.17
B27: Comparaison des méthodes | V27: Grosseur mm | W27: RR | X27: swebrec | Y27: %swebrec
B28: Grosseur mm | C28: RR | D28: swebrec | E28: %swebrec | K28: Grosseur mm | L28: RR | M28: swebrec | N28: %swebrec | V28: 1 | W28: =(1-EXP(-V28/$Y$25)^$Y$23)*100 -> 0.28271921 | X28: =(LN($Y$20/V28)/LN($Y$20/$Y$21))^$Y$24 -> 2650.484 | Y28: =100/(1+X28) -> 0.037714728
B29: 1 | C29: =(1-EXP(-B29/$C$24)^$C$22)*100 -> 0.42084961 | D29: =(LN($C$19/B29)/LN($C$19/$C$20))^$C$23 -> 2672.1369 | E29: =100/(1+D29) -> 0.037409232 | K29: 1 | L29: =(1-EXP(-K29/$M$24)^$M$22)*100 -> 0.4469587 | M29: =(LN($M$19/K29)/LN($M$19/$M$20))^$M$23 -> 3812.6129 | N29: =100/(1+M29) -> 0.026221854 | V29: 10 | W29: =(1-EXP(-V29/$Y$25)^$Y$23)*100 -> 2.7914934 | X29: =(LN($Y$20/V29)/LN($Y$20/$Y$21))^$Y$24 -> 577.00518 | Y29: =100/(1+X29) -> 0.17300883
B30: 10 | C30: =(1-EXP(-B30/$C$24)^$C$22)*100 -> 4.1296826 | D30: =(LN($C$19/B30)/LN($C$19/$C$20))^$C$23 -> 643.08823 | E30: =100/(1+D30) -> 0.15525823 | K30: 10 | L30: =(1-EXP(-K30/$M$24)^$M$22)*100 -> 4.3807527 | M30: =(LN($M$19/K30)/LN($M$19/$M$20))^$M$23 -> 788.65486 | N30: =100/(1+M30) -> 0.12663761 | V30: 50 | W30: =(1-EXP(-V30/$Y$25)^$Y$23)*100 -> 13.199674 | X30: =(LN($Y$20/V30)/LN($Y$20/$Y$21))^$Y$24 -> 128.10219 | Y30: =100/(1+X30) -> 0.77458017
B31: 50 | C31: =(1-EXP(-B31/$C$24)^$C$22)*100 -> 19.011972 | D31: =(LN($C$19/B31)/LN($C$19/$C$20))^$C$23 -> 148.97279 | E31: =100/(1+D31) -> 0.66678761 | K31: 50 | L31: =(1-EXP(-K31/$M$24)^$M$22)*100 -> 20.06691 | M31: =(LN($M$19/K31)/LN($M$19/$M$20))^$M$23 -> 157.56627 | N31: =100/(1+M31) -> 0.63065115 | V31: 100 | W31: =(1-EXP(-V31/$Y$25)^$Y$23)*100 -> 24.657034 | X31: =(LN($Y$20/V31)/LN($Y$20/$Y$21))^$Y$24 -> 54.727843 | Y31: =100/(1+X31) -> 1.7944351
B32: 100 | C32: =(1-EXP(-B32/$C$24)^$C$22)*100 -> 34.409392 | D32: =(LN($C$19/B32)/LN($C$19/$C$20))^$C$23 -> 62.893768 | E32: =100/(1+D32) -> 1.5650979 | K32: 100 | L32: =(1-EXP(-K32/$M$24)^$M$22)*100 -> 36.107011 | M32: =(LN($M$19/K32)/LN($M$19/$M$20))^$M$23 -> 61.26317 | N32: =100/(1+M32) -> 1.6060859 | V32: 200 | W32: =(1-EXP(-V32/$Y$25)^$Y$23)*100 -> 43.234375 | X32: =(LN($Y$20/V32)/LN($Y$20/$Y$21))^$Y$24 -> 19.040898 | Y32: =100/(1+X32) -> 4.9897965
B33: 200 | C33: =(1-EXP(-B33/$C$24)^$C$22)*100 -> 56.978722 | D33: =(LN($C$19/B33)/LN($C$19/$C$20))^$C$23 -> 20.485189 | E33: =100/(1+D33) -> 4.6543692 | K33: 200 | L33: =(1-EXP(-K33/$M$24)^$M$22)*100 -> 59.176859 | M33: =(LN($M$19/K33)/LN($M$19/$M$20))^$M$23 -> 18.057864 | N33: =100/(1+M33) -> 5.2471777 | V33: 300 | W33: =(1-EXP(-V33/$Y$25)^$Y$23)*100 -> 57.231095 | X33: =(LN($Y$20/V33)/LN($Y$20/$Y$21))^$Y$24 -> 8.9012286 | Y33: =100/(1+X33) -> 10.099757
B34: 300 | C34: =(1-EXP(-B34/$C$24)^$C$22)*100 -> 71.782082 | D34: =(LN($C$19/B34)/LN($C$19/$C$20))^$C$23 -> 8.7081725 | E34: =100/(1+D34) -> 10.3006 | K34: 300 | L34: =(1-EXP(-K34/$M$24)^$M$22)*100 -> 73.916875 | M34: =(LN($M$19/K34)/LN($M$19/$M$20))^$M$23 -> 7.1636224 | N34: =100/(1+M34) -> 12.249464 | V34: 500 | W34: =(1-EXP(-V34/$Y$25)^$Y$23)*100 -> 75.721964 | X34: =(LN($Y$20/V34)/LN($Y$20/$Y$21))^$Y$24 -> 2.6951352 | Y34: =100/(1+X34) -> 27.06261
B35: 500 | C35: =(1-EXP(-B35/$C$24)^$C$22)*100 -> 87.860291 | D35: =(LN($C$19/B35)/LN($C$19/$C$20))^$C$23 -> 2.0187346 | E35: =100/(1+D35) -> 33.126463 | K35: 500 | L35: =(1-EXP(-K35/$M$24)^$M$22)*100 -> 89.352049 | M35: =(LN($M$19/K35)/LN($M$19/$M$20))^$M$23 -> 1.5035642 | N35: =100/(1+M35) -> 39.943054 | V35: 700 | W35: =(1-EXP(-V35/$Y$25)^$Y$23)*100 -> 86.218421 | X35: =(LN($Y$20/V35)/LN($Y$20/$Y$21))^$Y$24 -> 0.97888164 | Y35: =100/(1+X35) -> 50.533593
B36: 700 | C36: =(1-EXP(-B36/$C$24)^$C$22)*100 -> 94.777342 | D36: =(LN($C$19/B36)/LN($C$19/$C$20))^$C$23 -> 0.49125364 | E36: =100/(1+D36) -> 67.057674 | K36: 700 | L36: =(1-EXP(-K36/$M$24)^$M$22)*100 -> 95.653172 | M36: =(LN($M$19/K36)/LN($M$19/$M$20))^$M$23 -> 0.34264513 | N36: =100/(1+M36) -> 74.479844 | V36: 900 | W36: =(1-EXP(-V36/$Y$25)^$Y$23)*100 -> 92.176801 | X36: =(LN($Y$20/V36)/LN($Y$20/$Y$21))^$Y$24 -> 0.38017388 | Y36: =100/(1+X36) -> 72.454639
B37: 900 | C37: =(1-EXP(-B37/$C$24)^$C$22)*100 -> 97.753146 | D37: =(LN($C$19/B37)/LN($C$19/$C$20))^$C$23 -> 0.10232181 | E37: =100/(1+D37) -> 90.71761 | K37: 900 | L37: =(1-EXP(-K37/$M$24)^$M$22)*100 -> 98.225488 | M37: =(LN($M$19/K37)/LN($M$19/$M$20))^$M$23 -> 0.069717115 | N37: =100/(1+M37) -> 93.482659 | V37: 1500 | W37: =(1-EXP(-V37/$Y$25)^$Y$23)*100 -> 98.568997 | X37: =(LN($Y$20/V37)/LN($Y$20/$Y$21))^$Y$24 -> 0.02000929 | Y37: =100/(1+X37) -> 98.038323
B38: 1460 | C38: =(1-EXP(-B38/$C$24)^$C$22)*100 -> 99.788218 | D38: =(LN($C$19/B38)/LN($C$19/$C$20))^$C$23 -> 0 | E38: =100/(1+D38) -> 100 | K38: 1443.67 | L38: =(1-EXP(-K38/$M$24)^$M$22)*100 -> 99.844623 | M38: =(LN($M$19/K38)/LN($M$19/$M$20))^$M$23 -> 1.3833801e-05 | N38: =100/(1+M38) -> 99.998617 | V38: 2500 | W38: =(1-EXP(-V38/$Y$25)^$Y$23)*100 -> 99.915653 | X38: =(LN($Y$20/V38)/LN($Y$20/$Y$21))^$Y$24 -> 2.3007274e-08 | Y38: =100/(1+X38) -> 99.999998
AD52: Le 4 était vraiment pas dans des conditions optimale on a juste poussé la roche
Y63: 3
Y64: Charge | Z64: =24*6 -> 144
...

Sheet Full blast 2025-11-11
A1: Date : | B1: 11-11-2025
A2: Note : | B2: Condition mise en place difficile
A3: Donnée initiale
A4: D | B4: 1 | C4: 220.45 | I4: Wip Frag | L4: Comparaison des méthodes | T4: Après correction
A5: D | B5: 5 | C5: 277.25 | G5: RR | I5: Xmax | J5: 3960 | L5: Grosseur mm | M5: RR | N5: swebrec | O5: %swebrec | T5: D | U5: 1 | V5: 190.91
A6: D | B6: 10 | C6: 330.22 | G6: X0 | H6: =C15 -> 2313.64 | I6: X50 | J6: 619.16 | L6: 1 | M6: =(1-EXP(-L6/$J$10)^$J$8)*100 -> 0.089982474 | N6: =(LN($J$5/L6)/LN($J$5/$J$6))^$J$9 -> 4416.5454 | O6: =100/(1+N6) -> 0.022637006 | T6: D | U6: 5 | V6: 255.17
A7: D | B7: 20 | C7: 392.96 | I7: Xc | J7: 802.44 | L7: 10 | M7: =(1-EXP(-L7/$J$10)^$J$8)*100 -> 0.89618989 | N7: =(LN($J$5/L7)/LN($J$5/$J$6))^$J$9 -> 710.6009 | O7: =100/(1+N7) -> 0.14052821 | T7: D | U7: 10 | V7: 310.57
A8: D | B8: 25 | C8: 424.21 | I8: n | J8: 2.55 | L8: 100 | M8: =(1-EXP(-L8/$J$10)^$J$8)*100 -> 8.6089819 | N8: =(LN($J$5/L8)/LN($J$5/$J$6))^$J$9 -> 46.492933 | O8: =100/(1+N8) -> 2.1055764 | T8: D | U8: 20 | V8: 377.54
A9: D | B9: 30 | C9: 455.48 | I9: b | J9: 5.61 | L9: 200 | M9: =(1-EXP(-L9/$J$10)^$J$8)*100 -> 16.476818 | N9: =(LN($J$5/L9)/LN($J$5/$J$6))^$J$9 -> 14.412863 | O9: =100/(1+N9) -> 6.4880872 | T9: D | U9: 25 | V9: 409.89
A10: D | B10: 40 | C10: 536.23 | I10: x90 | J10: 2832.61 | L10: 300 | M10: =(1-EXP(-L10/$J$10)^$J$8)*100 -> 23.667314 | N10: =(LN($J$5/L10)/LN($J$5/$J$6))^$J$9 -> 6.3554645 | O10: =100/(1+N10) -> 13.595334 | T10: D | U10: 30 | V10: 442.24
A11: D | B11: 50 | C11: 619.82 | L11: 500 | M11: =(1-EXP(-L11/$J$10)^$J$8)*100 -> 36.244512 | N11: =(LN($J$5/L11)/LN($J$5/$J$6))^$J$9 -> 1.8434569 | O11: =100/(1+N11) -> 35.16846 | T11: D | U11: 40 | V11: 525.67
A12: D | B12: 60 | C12: 725.82 | L12: 700 | M12: =(1-EXP(-L12/$J$10)^$J$8)*100 -> 46.749387 | N12: =(LN($J$5/L12)/LN($J$5/$J$6))^$J$9 -> 0.68124294 | O12: =100/(1+N12) -> 59.479804 | T12: D | U12: 50 | V12: 618.58
A13: D | B13: 70 | C13: 892.94 | L13: 900 | M13: =(1-EXP(-L13/$J$10)^$J$8)*100 -> 55.523394 | N13: =(LN($J$5/L13)/LN($J$5/$J$6))^$J$9 -> 0.28285522 | O13: =100/(1+N13) -> 77.951119 | T13: D | U13: 60 | V13: 742.3
A14: D | B14: 80 | C14: 1347.29 | L14: 1500 | M14: =(1-EXP(-L14/$J$10)^$J$8)*100 -> 74.084909 | N14: =(LN($J$5/L14)/LN($J$5/$J$6))^$J$9 -> 0.026393749 | O14: =100/(1+N14) -> 97.428497 | T14: D | U14: 70 | V14: 929
A15: D | B15: 90 | C15: 2313.64 | L15: 3000 | M15: =(1-EXP(-L15/$J$10)^$J$8)*100 -> 93.284081 | N15: =(LN($J$5/L15)/LN($J$5/$J$6))^$J$9 -> 2.3529771e-05 | O15: =100/(1+N15) -> 99.997647 | T15: D | U15: 80 | V15: 1700.23
A16: Xmax | B16: 99 | C16: 3280 | L16: 3170 | M16: =(1-EXP(-L16/$J$10)^$J$8)*100 -> 94.237095 | N16: =(LN($J$5/L16)/LN($J$5/$J$6))^$J$9 -> 6.7985073e-06 | O16: =100/(1+N16) -> 99.99932 | T16: D | U16: 90 | V16: 2830.12
C17: 3810mm | T17: Xmax | U17: 99 | V17: 3947.01
V18: 3810mm
Z22: Information sur le Sautage
Z23: Nombre | AA23: 85 | AB23: Trous
Z24: Diamètre | AA24: 115 | AB24: mm
Z25: Masse d'explosif | AA25: 13864 | AB25: kg
Z26: Aire Excavation | AA26: 1212.66 | AB26: m2 | AC26: Très approx
Z27: Hauteur | AA27: 13.4 | AB27: m | AC27: Les gars disaient 15
Z28: Volume Excavé | AA28: =AA26*AA27 -> 16249.644 | AB28: m3
Z29: Facteur poudre | AA29: =AA25/AA28 -> 0.85318792 | AB29: kg/m3
Z30: Dip | AA30: 87 | AB30: Degré
Z31: DipD | AA31: 130 | AB31: Degré

Sheet SHB phase 3
D3: P3-6 | J3: P3-5 | K3: double hole | O3: P3-1,2,3,4
D4: Dip | E4: 84 | X4: P3-4
D5: Dip D | E5: 124
D6: q | J6: q
W7: D | X7: 1 | Y7: 220.94
W8: D | X8: 5 | Y8: 286.22
D9: D | E9: 1 | F9: 17.78 | J9: D | K9: 1 | L9: 150 | O9: D | P9: 1 | Q9: 206 | W9: D | X9: 10 | Y9: 340.25
D10: D | E10: 5 | F10: 222.21 | J10: D | K10: 5 | L10: 224.98 | O10: D | P10: 5 | Q10: 280 | W10: D | X10: 20 | Y10: 416.62
D11: D | E11: 10 | F11: 276.35 | J11: D | K11: 10 | L11: 269.7 | O11: D | P11: 10 | Q11: 345.5 | W11: D | X11: 25 | Y11: 454.8
D12: D | E12: 20 | F12: 350.68 | J12: D | K12: 20 | L12: 340.9 | O12: D | P12: 20 | Q12: 452.79 | W12: D | X12: 30 | Y12: 494.53
D13: D | E13: 25 | F13: 378.05 | J13: D | K13: 25 | L13: 366.7 | O13: D | P13: 25 | Q13: 498 | W13: D | X13: 40 | Y13: 574.97
D14: D | E14: 30 | F14: 405.41 | J14: D | K14: 30 | L14: 392.57 | O14: D | P14: 30 | Q14: 547.07 | W14: D | X14: 50 | Y14: 655.41
D15: D | E15: 40 | F15: 460.13 | J15: D | K15: 40 | L15: 444.26 | O15: D | P15: 40 | Q15: 644 | W15: D | X15: 60 | Y15: 748.58
D16: D | E16: 50 | F16: 536.87 | J16: D | K16: 50 | L16: 505.83 | O16: D | P16: 50 | Q16: 752.8 | W16: D | X16: 70 | Y16: 847.7
D17: D | E17: 60 | F17: 615.29 | J17: D | K17: 60 | L17: 573.5 | O17: D | P17: 60 | Q17: 868 | W17: D | X17: 80 | Y17: 946.82
D18: D | E18: 70 | F18: 711.07 | J18: D | K18: 70 | L18: 641.18 | O18: D | P18: 70 | Q18: 983.37 | W18: D | X18: 90 | Y18: 1152.01
D19: D | E19: 80 | F19: 896.73 | J19: D | K19: 80 | L19: 749 | O19: D | P19: 80 | Q19: 1470.48 | W19: D | X19: 99 | Y19: 1447.2
D20: D | E20: 90 | F20: 1224.38 | J20: D | K20: 90 | L20: 914.12 | O20: D | P20: 90 | Q20: 2020 | W20: Xmax | X20: 1480
D21: D | E21: 99 | F21: 1679.44 | J21: D | K21: 99 | L21: 1134.58 | O21: D | P21: 99 | Q21: 2515 | W21: x50 | X21: 655.41
D22: Xmax | E22: 1730 | J22: Xmax | K22: 1170 | O22: Xmax | P22: 2240 | W22: Xc | X22: 780.3
D23: x50 | E23: 543.98 | J23: x50 | K23: 556 | O23: x50 | P23: 733.29 | W23: n | X23: 4.09
D24: Xc | E24: 628.89 | J24: Xc | K24: 634.11 | O24: Xc | P24: 886.06 | W24: b | X24: 3.26
D25: n | E25: 2.75 | J25: n | K25: 4.63 | O25: n | P25: 2.14 | W25: x90 | X25: =Y18 -> 1152.01
D26: b | E26: 4.95 | J26: b | K26: 4.18 | O26: b | P26: 3.89
D27: x90 | E27: =F20 -> 1224.38 | J27: x90 | K27: =L20 -> 914.12 | O27: x90 | P27: =Q20 -> 2020
W45: Grosseur mm | X45: swebrec | Y45: %swebrec
J46: Grosseur mm | K46: swebrec | L46: %swebrec | P46: Grosseur mm | Q46: swebrec | R46: %swebrec | W46: 1 | X46: =(LN($X$20/W46)/LN($X$20/$X$21))^$X$23 -> 7858.0958 | Y46: =100/(1+X46) -> 0.01272411
E47: Grosseur mm | F47: swebrec | G47: %swebrec | J47: 1 | K47: =(LN($K$22/J47)/LN($K$22/$K$23))^$K$26 -> 12191.992 | L47: =100/(1+K47) -> 0.0082014323 | P47: 1 | Q47: =(LN($P$22/P47)/LN($P$22/$P$23))^$P$26 -> 1841.2411 | R47: =100/(1+Q47) -> 0.054281713 | W47: 10 | X47: =(LN($X$20/W47)/LN($X$20/$X$21))^$X$23 -> 1667.9108 | Y47: =100/(1+X47) -> 0.05991932
E48: 1 | F48: =(LN($E$22/E48)/LN($E$22/$E$23))^$E$26 -> 10125.933 | G48: =100/(1+F48) -> 0.0098746585 | J48: 10 | K48: =(LN($K$22/J48)/LN($K$22/$K$23))^$K$26 -> 2344.6267 | L48: =100/(1+K48) -> 0.04263253 | P48: 10 | Q48: =(LN($P$22/P48)/LN($P$22/$P$23))^$P$26 -> 463.65351 | R48: =100/(1+Q48) -> 0.21521413 | W48: 100 | X48: =(LN($X$20/W48)/LN($X$20/$X$21))^$X$23 -> 133.38769 | Y48: =100/(1+X48) -> 0.74411577
E49: 10 | F49: =(LN($E$22/E49)/LN($E$22/$E$23))^$E$26 -> 1626.9932 | G49: =100/(1+F49) -> 0.061425319 | J49: 100 | K49: =(LN($K$22/J49)/LN($K$22/$K$23))^$K$26 -> 148.13342 | L49: =100/(1+K49) -> 0.67054051 | P49: 100 | Q49: =(LN($P$22/P49)/LN($P$22/$P$23))^$P$26 -> 53.687105 | R49: =100/(1+Q49) -> 1.8285846 | W49: 200 | X49: =(LN($X$20/W49)/LN($X$20/$X$21))^$X$23 -> 39.527811 | Y49: =100/(1+X49) -> 2.4674415
E50: 100 | F50: =(LN($E$22/E50)/LN($E$22/$E$23))^$E$26 -> 86.812305 | G50: =100/(1+F50) -> 1.1387926 | J50: 200 | K50: =(LN($K$22/J50)/LN($K$22/$K$23))^$K$26 -> 37.129817 | L50: =100/(1+K50) -> 2.6226195 | P50: 200 | Q50: =(LN($P$22/P50)/LN($P$22/$P$23))^$P$26 -> 20.124682 | R50: =100/(1+Q50) -> 4.7337992 | W50: 300 | X50: =(LN($X$20/W50)/LN($X$20/$X$21))^$X$23 -> 15.660197 | Y50: =100/(1+X50) -> 6.0023301
E51: 200 | F51: =(LN($E$22/E51)/LN($E$22/$E$23))^$E$26 -> 21.861601 | G51: =100/(1+F51) -> 4.3741468 | J51: 300 | K51: =(LN($K$22/J51)/LN($K$22/$K$23))^$K$26 -> 12.483703 | L51: =100/(1+K51) -> 7.4163603 | P51: 300 | Q51: =(LN($P$22/P51)/LN($P$22/$P$23))^$P$26 -> 9.8480894 | R51: =100/(1+Q51) -> 9.2182131 | W51: 500 | X51: =(LN($X$20/W51)/LN($X$20/$X$21))^$X$23 -> 3.2329098 | Y51: =100/(1+X51) -> 23.624411
E52: 300 | F52: =(LN($E$22/E52)/LN($E$22/$E$23))^$E$26 -> 7.8014582 | G52: =100/(1+F52) -> 11.361754 | J52: 500 | K52: =(LN($K$22/J52)/LN($K$22/$K$23))^$K$26 -> 1.7463897 | L52: =100/(1+K52) -> 36.411439 | P52: 500 | Q52: =(LN($P$22/P52)/LN($P$22/$P$23))^$P$26 -> 3.1485649 | R52: =100/(1+Q52) -> 24.104721 | W52: 700 | X52: =(LN($X$20/W52)/LN($X$20/$X$21))^$X$23 -> 0.70849301 | Y52: =100/(1+X52) -> 58.531114
E53: 500 | F53: =(LN($E$22/E53)/LN($E$22/$E$23))^$E$26 -> 1.4164522 | G53: =100/(1+F53) -> 41.382983 | J53: 700 | K53: =(LN($K$22/J53)/LN($K$22/$K$23))^$K$26 -> 0.21258784 | L53: =100/(1+K53) -> 82.468252 | P53: 700 | Q53: =(LN($P$22/P53)/LN($P$22/$P$23))^$P$26 -> 1.1718348 | R53: =100/(1+Q53) -> 46.044017 | W53: 900 | X53: =(LN($X$20/W53)/LN($X$20/$X$21))^$X$23 -> 0.13301851 | Y53: =100/(1+X53) -> 88.259812
E54: 700 | F54: =(LN($E$22/E54)/LN($E$22/$E$23))^$E$26 -> 0.29613725 | G54: =100/(1+F54) -> 77.152323 | J54: 900 | K54: =(LN($K$22/J54)/LN($K$22/$K$23))^$K$26 -> 0.012819447 | L54: =100/(1+K54) -> 98.734281 | P54: 900 | Q54: =(LN($P$22/P54)/LN($P$22/$P$23))^$P$26 -> 0.45458914 | R54: =100/(1+Q54) -> 68.747935 | W54: 1370 | X54: =(LN($X$20/W54)/LN($X$20/$X$21))^$X$23 -> 6.5381068e-05 | Y54: =100/(1+X54) -> 99.993462
E55: 900 | F55: =(LN($E$22/E55)/LN($E$22/$E$23))^$E$26 -> 0.059152431 | G55: =100/(1+F55) -> 94.415116 | J55: 1170 | K55: =(LN($K$22/J55)/LN($K$22/$K$23))^$K$26 -> 0 | L55: =100/(1+K55) -> 100 | P55: 1370 | Q55: =(LN($P$22/P55)/LN($P$22/$P$23))^$P$26 -> 0.041127872 | R55: =100/(1+Q55) -> 96.049681 | W55: 1480 | X55: =(LN($X$20/W55)/LN($X$20/$X$21))^$X$23 -> 0 | Y55: =100/(1+X55) -> 100
E56: 1500 | F56: =(LN($E$22/E56)/LN($E$22/$E$23))^$E$26 -> 3.1645111e-05 | G56: =100/(1+F56) -> 99.996836 | P56: 2000 | Q56: =(LN($P$22/P56)/LN($P$22/$P$23))^$P$26 -> 0.00013643452 | R56: =100/(1+Q56) -> 99.986358
E57: 1730 | F57: =(LN($E$22/E57)/LN($E$22/$E$23))^$E$26 -> 0 | G57: =100/(1+F57) -> 100 | P57: 2240 | Q57: =(LN($P$22/P57)/LN($P$22/$P$23))^$P$26 -> 0 | R57: =100/(1+Q57) -> 100

Sheet Full blast phase 3
C8: D | D8: 1 | E8: 16.27
C9: D | D9: 5 | E9: 215.47
C10: D | D10: 10 | E10: 291.48
C11: D | D11: 15 | E11: 339.66
C12: D | D12: 20 | E12: 374.59
C13: D | D13: 25 | E13: 409.52
C14: D | D14: 40 | E14: 526.57
C15: D | D15: 50 | E15: 613.44
C16: D | D16: 60 | E16: 715.6
C17: D | D17: 70 | E17: 971.19
C18: D | D18: 80 | E18: 1117.31
C19: D | D19: 90 | E19: 1798.65
... C21: Xmax | D21: 100 | E21: 2480
C22: Xmax | D22: =E21 -> 2480
C23: x50 | D23: =E15 -> 613.44
C24: Xc | D24: 765.39
C25: n | D25: 1.58
C26: b | D26: 4.04
C27: x90 | D27: =E19 -> 1798.65
C30: Grosseur mm | D30: swebrec | E30: %swebrec
C31: 1 | D31: =(LN($D$22/C31)/LN($D$22/$D$23))^$D$26 -> 1049.9132 | E31: =100/(1+D31) -> 0.095155337
C32: 10 | D32: =(LN($D$22/C32)/LN($D$22/$D$23))^$D$26 -> 256.35196 | E32: =100/(1+D32) -> 0.38857291
C33: 100 | D33: =(LN($D$22/C33)/LN($D$22/$D$23))^$D$26 -> 28.855866 | E33: =100/(1+D33) -> 3.3494256
C34: 200 | D34: =(LN($D$22/C34)/LN($D$22/$D$23))^$D$26 -> 10.803048 | E34: =100/(1+D34) -> 8.4723875
C35: 300 | D35: =(LN($D$22/C35)/LN($D$22/$D$23))^$D$26 -> 5.3143275 | E35: =100/(1+D35) -> 15.836999
C36: 500 | D36: =(LN($D$22/C36)/LN($D$22/$D$23))^$D$26 -> 1.736514 | E36: =100/(1+D36) -> 36.542843
C37: 700 | D37: =(LN($D$22/C37)/LN($D$22/$D$23))^$D$26 -> 0.66964741 | E37: =100/(1+D37) -> 59.892885
C38: 900 | D38: =(LN($D$22/C38)/LN($D$22/$D$23))^$D$26 -> 0.27366975 | E38: =100/(1+D38) -> 78.513288
C39: 1500 | D39: =(LN($D$22/C39)/LN($D$22/$D$23))^$D$26 -> 0.016110416 | E39: =100/(1+D39) -> 98.414501
C40: 1730 | D40: =(LN($D$22/C40)/LN($D$22/$D$23))^$D$26 -> 0.004184303 | E40: =100/(1+D40) -> 99.583313

Sheet Fulll blast 24-11-2025
A1: Premier essai Fragmentation Wipfrag non travaillée | T1: Granulo travaillée
A2: D | B2: 1 | C2: 22.77 | M2: Comparaison des méthodes | T2: D | U2: 1 | V2: 18.85
A3: D | B3: 5 | C3: 260.68 | M3: Grosseur mm | N3: RR | O3: swebrec | P3: %swebrec | T3: D | U3: 5 | V3: 215.27
A4: D | B4: 10 | C4: 320.79 | D4: =LN(1/(1-(B4/100))) -> 0.10536052 | E4: =LN(C4/10) -> 3.4682016 | G4: Wip frag data | M4: 1 | N4: =(1-EXP(-M4/$H$7)^$H$6)*100 -> 0.083108619 | O4: =(LN($H$11/M4)/LN($H$11/$H$9))^$H$12 -> 819.25809 | P4: =100/(1+O4) -> 0.12191285 | T4: D | U4: 10 | V4: 276.19
A5: D | B5: 15 | C5: 355.77 | D5: =LN(1/(1-(B5/100))) -> 0.16251893 | E5: =LN(C5/10) -> 3.5716994 | G5: RR | M5: 10 | N5: =(1-EXP(-M5/$H$7)^$H$6)*100 -> 0.8279849 | O5: =(LN($H$11/M5)/LN($H$11/$H$9))^$H$12 -> 191.58255 | P5: =100/(1+O5) -> 0.51925786 | T5: D | U5: 15 | V5: 319.38
A6: D | B6: 20 | C6: 390.75 | D6: =LN(1/(1-(B6/100))) -> 0.22314355 | E6: =LN(C6/10) -> 3.6654829 | G6: n | H6: 1.84 | M6: 100 | N6: =(1-EXP(-M6/$H$7)^$H$6)*100 -> 7.9780613 | O6: =(LN($H$11/M6)/LN($H$11/$H$9))^$H$12 -> 21.05043 | P6: =100/(1+O6) -> 4.5350589 | T6: D | U6: 20 | V6: 351.19
A7: D | B7: 25 | C7: 422.31 | D7: =LN(1/(1-(B7/100))) -> 0.28768207 | E7: =LN(C7/10) -> 3.7431545 | G7: X90 | H7: =C13 -> 2213.05 | M7: 200 | N7: =(1-EXP(-M7/$H$7)^$H$6)*100 -> 15.319628 | O7: =(LN($H$11/M7)/LN($H$11/$H$9))^$H$12 -> 7.982373 | P7: =100/(1+O7) -> 11.132916 | T7: D | U7: 25 | V7: 383
A8: D | B8: 40 | C8: 516.95 | D8: =LN(1/(1-(B8/100))) -> 0.51082562 | E8: =LN(C8/10) -> 3.9453611 | G8: Swebrec | M8: 300 | N8: =(1-EXP(-M8/$H$7)^$H$6)*100 -> 22.07548 | O8: =(LN($H$11/M8)/LN($H$11/$H$9))^$H$12 -> 4.0107989 | P8: =100/(1+O8) -> 19.956897 | T8: D | U8: 40 | V8: 481.28
A9: D | B9: 50 | C9: 594.2 | D9: =LN(1/(1-(B9/100))) -> 0.69314718 | E9: =LN(C9/10) -> 4.0846309 | G9: x50 | H9: 571.89 | M9: 500 | N9: =(1-EXP(-M9/$H$7)^$H$6)*100 -> 34.013227 | O9: =(LN($H$11/M9)/LN($H$11/$H$9))^$H$12 -> 1.3887789 | P9: =100/(1+O9) -> 41.862393 | T9: D | U9: 50 | V9: 560.6
A10: D | B10: 60 | C10: 696.85 | D10: =LN(1/(1-(B10/100))) -> 0.91629073 | E10: =LN(C10/10) -> 4.2439851 | G10: xc | H10: 736.38 | M10: 700 | N10: =(1-EXP(-M10/$H$7)^$H$6)*100 -> 44.122155 | O10: =(LN($H$11/M10)/LN($H$11/$H$9))^$H$12 -> 0.57883391 | P10: =100/(1+O10) -> 63.337885 | T10: D | U10: 60 | V10: 675.63
A11: D | B11: 70 | C11: 849.97 | D11: =LN(1/(1-(B11/100))) -> 1.2039728 | E11: =LN(C11/10) -> 4.442616 | G11: xmax | H11: 3120 | M11: 900 | N11: =(1-EXP(-M11/$H$7)^$H$6)*100 -> 52.682433 | O11: =(LN($H$11/M11)/LN($H$11/$H$9))^$H$12 -> 0.26177524 | P11: =100/(1+O11) -> 79.253418 | T11: D | U11: 70 | V11: 823.25
A12: D | B12: 80 | C12: 1256.112 | D12: =LN(1/(1-(B12/100))) -> 1.6094379 | E12: =LN(C12/10) -> 4.8331914 | G12: b | H12: 4.31 | M12: 1500 | N12: =(1-EXP(-M12/$H$7)^$H$6)*100 -> 71.267681 | O12: =(LN($H$11/M12)/LN($H$11/$H$9))^$H$12 -> 0.026757767 | P12: =100/(1+O12) -> 97.393955 | T12: D | U12: 80 | V12: 1101.3
A13: D | B13: 90 | C13: 2213.05 | D13: =LN(1/(1-(B13/100))) -> 2.3025851 | E13: =LN(C13/10) -> 5.3995418 | M13: 3000 | N13: =(1-EXP(-M13/$H$7)^$H$6)*100 -> 91.744538 | O13: =(LN($H$11/M13)/LN($H$11/$H$9))^$H$12 -> 8.882155e-08 | P13: =100/(1+O13) -> 99.999991 | T13: D | U13: 90 | V13: 1552.43
A14: D | B14: 99 | C14: 3074.31 | M14: 3120 | N14: =(1-EXP(-M14/$H$7)^$H$6)*100 -> 92.528445 | O14: =(LN($H$11/M14)/LN($H$11/$H$9))^$H$12 -> 0 | P14: =100/(1+O14) -> 100 | T14: D | U14: 99 | V14: 2925.92
A15: Xmax | B15: 100 | C15: 3170 | T15: Xmax | U15: 100 | V15: 3120
V21: Information sur le Sautage
V22: Nombre | W22: 76 | X22: Trous
V23: Diamètre | W23: 115 | X23: mm
V24: Masse d'explosif | W24: 11943 | X24: kg
V25: Aire Excavation | W25: 1166.45 | X25: m2
V26: Hauteur | W26: 13 | X26: m
V27: Volume Excavé | W27: =W25*W26 -> 15163.85 | X27: m3
V28: Facteur poudre | W28: =W24/W27 -> 0.78759682 | X28: kg/m3
V29: Dip | W29: 82 | X29: Degré
V30: DipD | W30: 54 | X30: Degré

Sheet Full blast 18-03-2026
E1: Fragmentation
C9: Granulo travaillée
C10: D | D10: 1 | E10: 147.61
C11: D | D11: 5 | E11: 251.73
C12: D | D12: 10 | E12: 311.8
C13: D | D13: 15 | E13: 345.41
C14: D | D14: 20 | E14: 377.03
C15: D | D15: 25 | E15: 408.65
C16: D | D16: 40 | E16: 520.72
C17: D | D17: 50 | E17: 611.48
C18: D | D18: 60 | E18: 715.86
C19: D | D19: 70 | E19: 864.83
C20: D | D20: 80 | E20: 1095.21
C21: D | D21: 90 | E21: 2122.6
... C23: Xmax | D23: 100 | E23: 3150
C26: Wip frag data
C27: RR
C28: n | D28: 2.12
C29: X90 | D29: =E21 -> 2122.6
C30: Swebrec
C31: x50 | D31: 611.48
C32: xc | D32: 763.53
C33: xmax | D33: =E23 -> 3150
C34: b | D34: 5.21
C36: Comparaison des méthodes
C37: Grosseur mm | D37: RR | E37: swebrec | F37: %swebrec
C38: 1 | D38: =(1-EXP(-C38/$D$29)^$D$28)*100 -> 0.099827648 | E38: =(LN($D$33/C38)/LN($D$33/$D$31))^$D$34 -> 4002.2957 | F38: =100/(1+E38) -> 0.024979419
C39: 10 | D39: =(1-EXP(-C39/$D$29)^$D$28)*100 -> 0.99380389 | E39: =(LN($D$33/C39)/LN($D$33/$D$31))^$D$34 -> 692.69966 | F39: =100/(1+E39) -> 0.1441546
C40: 100 | D40: =(1-EXP(-C40/$D$29)^$D$28)*100 -> 9.505174 | E40: =(LN($D$33/C40)/LN($D$33/$D$31))^$D$34 -> 48.271711 | F40: =100/(1+E40) -> 2.0295622
C41: 200 | D41: =(1-EXP(-C41/$D$29)^$D$28)*100 -> 18.106865 | E41: =(LN($D$33/C41)/LN($D$33/$D$31))^$D$34 -> 15.004029 | F41: =100/(1+E41) -> 6.2484264
C42: 300 | D42: =(1-EXP(-C42/$D$29)^$D$28)*100 -> 25.89095 | E42: =(LN($D$33/C42)/LN($D$33/$D$31))^$D$34 -> 6.5501418 | F42: =100/(1+E42) -> 13.244784
C43: 500 | D43: =(1-EXP(-C43/$D$29)^$D$28)*100 -> 39.309775 | E43: =(LN($D$33/C43)/LN($D$33/$D$31))^$D$34 -> 1.8282687 | F43: =100/(1+E43) -> 35.35732
C44: 700 | D44: =(1-EXP(-C44/$D$29)^$D$28)*100 -> 50.298872 | E44: =(LN($D$33/C44)/LN($D$33/$D$31))^$D$34 -> 0.63861782 | F44: =100/(1+E44) -> 61.027043
C45: 900 | D45: =(1-EXP(-C45/$D$29)^$D$28)*100 -> 59.298188 | E45: =(LN($D$33/C45)/LN($D$33/$D$31))^$D$34 -> 0.24635443 | F45: =100/(1+E45) -> 80.233999
C46: 1500 | D46: =(1-EXP(-C46/$D$29)^$D$28)*100 -> 77.645949 | E46: =(LN($D$33/C46)/LN($D$33/$D$31))^$D$34 -> 0.016079652 | F46: =100/(1+E46) -> 98.417481
C47: 3000 | D47: =(1-EXP(-C47/$D$29)^$D$28)*100 -> 95.002964 | E47: =(LN($D$33/C47)/LN($D$33/$D$31))^$D$34 -> 1.1165407e-08 | F47: =100/(1+E47) -> 99.999999
C48: 3150 | D48: =(1-EXP(-C48/$D$29)^$D$28)*100 -> 95.698221 | E48: =(LN($D$33/C48)/LN($D$33/$D$31))^$D$34 -> 0 | F48: =100/(1+E48) -> 100

Sheet Full blast 2026-05-11
A1: Description : Diam : 4 1/2'' B:3,4m S: 3,9m H: 16m Q : 170 Kg
B7: Granulo travaillée
B8: D | C8: 1 | D8: 18.37
B9: D | C9: 5 | D9: 235.72
B10: D | C10: 10 | D10: 297.46
B11: D | C11: 15 | D11: 342.89
B12: D | C12: 20 | D12: 381.32
B13: D | C13: 25 | D13: 419.75
B14: D | C14: 40 | D14: 555.9
B15: D | C15: 50 | D15: 655.34
B16: D | C16: 60 | D16: 799.15
B17: D | C17: 70 | D17: 958.39
B18: D | C18: 80 | D18: 1658.13
B19: D | C19: 90 | D19: 2549.07
... B21: Xmax | C21: 100 | D21: 3440
B24: Wip frag data
B25: RR
B26: n | C26: 1.72
B27: X90 | C27: =D19 -> 2549.07
B28: Swebrec
B29: x50 | C29: 655.34
B30: xc | C30: 850.11
B31: xmax | C31: 3440
B32: b | C32: 4.72
B34: Comparaison des méthodes
B35: Grosseur mm | C35: RR | D35: swebrec | E35: %swebrec
B36: 1 | C36: =(1-EXP(-B36/$C$27)^$C$26)*100 -> 0.067452829 | D36: =(LN($C$31/B36)/LN($C$31/$C$29))^$C$32 -> 1829.9151 | E36: =100/(1+D36) -> 0.054617498
B37: 10 | C37: =(1-EXP(-B37/$C$27)^$C$26)*100 -> 0.67248453 | D37: =(LN($C$31/B37)/LN($C$31/$C$29))^$C$32 -> 381.21078 | E37: =100/(1+D37) -> 0.26163574
B38: 100 | C38: =(1-EXP(-B38/$C$27)^$C$26)*100 -> 6.5249462 | D38: =(LN($C$31/B38)/LN($C$31/$C$29))^$C$32 -> 35.780058 | E38: =100/(1+D38) -> 2.7188646
B39: 200 | C39: =(1-EXP(-B39/$C$27)^$C$26)*100 -> 12.624143 | D39: =(LN($C$31/B39)/LN($C$31/$C$29))^$C$32 -> 12.784223 | E39: =100/(1+D39) -> 7.2546706
B40: 300 | C40: =(1-EXP(-B40/$C$27)^$C$26)*100 -> 18.325371 | D40: =(LN($C$31/B40)/LN($C$31/$C$29))^$C$32 -> 6.1870607 | E40: =100/(1+D40) -> 13.913894
B41: 500 | C41: =(1-EXP(-B41/$C$27)^$C$26)*100 -> 28.636093 | D41: =(LN($C$31/B41)/LN($C$31/$C$29))^$C$32 -> 2.0409584 | E41: =100/(1+D41) -> 32.88437
B42: 700 | C42: =(1-EXP(-B42/$C$27)^$C$26)*100 -> 37.645175 | D42: =(LN($C$31/B42)/LN($C$31/$C$29))^$C$32 -> 0.82571676 | E42: =100/(1+D42) -> 54.773009
B43: 900 | C43: =(1-EXP(-B43/$C$27)^$C$26)*100 -> 45.516937 | D43: =(LN($C$31/B43)/LN($C$31/$C$29))^$C$32 -> 0.36701035 | E43: =100/(1+D43) -> 73.152336
B44: 1500 | C44: =(1-EXP(-B44/$C$27)^$C$26)*100 -> 63.655738 | D44: =(LN($C$31/B44)/LN($C$31/$C$29))^$C$32 -> 0.03815361 | E44: =100/(1+D44) -> 96.324859
B45: 3000 | C45: =(1-EXP(-B45/$C$27)^$C$26)*100 -> 86.790946 | D45: =(LN($C$31/B45)/LN($C$31/$C$29))^$C$32 -> 7.7034333e-06 | E45: =100/(1+D45) -> 99.99923
B46: 3440 | C46: =(1-EXP(-B46/$C$27)^$C$26)*100 -> 90.184037 | D46: =(LN($C$31/B46)/LN($C$31/$C$29))^$C$32 -> 0 | E46: =100/(1+D46) -> 100

Sheet ISEE 2026
C2: 46153 | G2: 46099 | K2: 46227
C3: 220 | G3: 124 | K3: 220
C4: Granulo travaillée | G4: Granulo travaillée | K4: Granulo
C5: D | D5: 1 | E5: 18.17 | G5: D | H5: 1 | I5: 147.61 | K5: D | L5: 1 | M5: ='2026-07-23'!F6 -> 20.49
C6: D | D6: 5 | E6: 231.34 | G6: D | H6: 5 | I6: 251.73 | L6: 5 | M6: ='2026-07-23'!F7 -> 219.93
C7: D | D7: 10 | E7: 292.09 | G7: D | H7: 10 | I7: 311.8 | L7: 10 | M7: ='2026-07-23'!F8 -> 267.78
C8: D | D8: 15 | E8: 339.75 | G8: D | H8: 15 | I8: 345.41 | L8: 15 | M8: ='2026-07-23'!F9 -> 315.64
C9: D | D9: 20 | E9: 378.91 | G9: D | H9: 20 | I9: 377.03 | L9: 20 | M9: ='2026-07-23'!F10 -> 344.78
C10: D | D10: 25 | E10: 418 | G10: D | H10: 25 | I10: 408.65 | L10: 25 | M10: ='2026-07-23'!F11 -> 373.77
C11: D | D11: 40 | E11: 556.13 | G11: D | H11: 40 | I11: 520.72 | L11: 40 | M11: ='2026-07-23'!F12 -> 460.76
C12: D | D12: 50 | E12: 656.97 | G12: D | H12: 50 | I12: 611.48 | L12: 50 | M12: ='2026-07-23'!F13 -> 540.75
C13: D | D13: 60 | E13: 802.7 | G13: D | H13: 60 | I13: 715.86 | L13: 60 | M13: ='2026-07-23'!F14 -> 622.05
C14: D | D14: 70 | E14: 962.49 | G14: D | H14: 70 | I14: 864.83 | L14: 70 | M14: ='2026-07-23'!F15 -> 729.86
C15: D | D15: 80 | E15: 1675.24 | G15: D | H15: 80 | I15: 1095.21 | L15: 80 | M15: ='2026-07-23'!F16 -> 907.66
C16: D | D16: 90 | E16: 2557.62 | G16: D | H16: 90 | I16: 2122.6 | L16: 90 | M16: ='2026-07-23'!F17 -> 1645.53
C17: D | D17: 99 | E17: 3351.76 | G17: D | H17: 99 | I17: 3047.26 | L17: 99 | M17: ='2026-07-23'!F18 -> 2855.55
C18: Xmax | D18: 100 | E18: 3440 | G18: Xmax | H18: 100 | I18: 3150 | L18: 100 | M18: ='2026-07-23'!F19 -> 2990

Sheet 2026-07-23
B2: 46226
B3: 220
B4: non travaillée | E4: travaillée
B5: Granulo
B6: D | C6: 1 | D6: 21.42 | E6: 1 | F6: 20.49
C7: 5 | D7: 262.22 | E7: 5 | F7: 219.93
C8: 10 | D8: 322.91 | E8: 10 | F8: 267.78 | G8: 0.01 | H8: =(G8*3/4/PI())^(1/3)*1000 -> 133.65046 | I8: =SQRT(G8/1.5)*1000 -> 81.649658 | K8: 10 | L8: =H8*2 -> 267.30092
C9: 15 | D9: 350.46 | E9: 15 | F9: 315.64 | K9: 25 | L9: =H11*2 -> 575.88238
C10: 20 | D10: 378.01 | E10: 20 | F10: 344.78 | K10: 60 | L10: =H14*2 -> 1240.701
C11: 25 | D11: 405.56 | E11: 25 | F11: 373.77 | G11: 0.1 | H11: =(G11*3/4/PI())^(1/3)*1000 -> 287.94119 | I11: =SQRT(G11/1.5)*1000 -> 258.19889 | K11: 100 | L11: =H19*2 -> 4243.1377
C12: 40 | D12: 493.53 | E12: 40 | F12: 460.76
C13: 50 | D13: 560.72 | E13: 50 | F13: 540.75
C14: 60 | D14: 627.92 | E14: 60 | F14: 622.05 | G14: 1 | H14: =(G14*3/4/PI())^(1/3)*1000 -> 620.35049 | I14: =SQRT(G14/1.5)*1000 -> 816.49658
C15: 70 | D15: 715.49 | E15: 70 | F15: 729.86
C16: 80 | D16: 879.66 | E16: 80 | F16: 907.66
C17: 90 | D17: 1394.09 | E17: 90 | F17: 1645.53
C18: 99 | D18: 2722.41 | E18: 99 | F18: 2855.55
C19: 100 | D19: 2870 | E19: 100 | F19: 2990 | G19: 40 | H19: =(G19*3/4/PI())^(1/3)*1000 -> 2121.5688 | I19: =SQRT(G19/1.5)*1000 -> 5163.9778
